Workbook

Sheet Ledger
A1: transaction_id | B1: user_id | C1: merchant_id | D1: transaction_time | E1: amount_inr | F1: payment_method | G1: status | H1: risk_score
A2: TXN100000 | B2: 350 | C2: 16 | D2: 46051.467 | E2: 2999 | F2: Wallet | G2: captured | H2: 85
A3: TXN100001 | B3: 287 | C3: 27 | D3: 46026.492 | E3: 49 | F3: UPI | G3: captured | H3: 79
A4: TXN100002 | B4: 122 | C4: 11 | D4: 46046.208 | E4: 1499 | F4: Wallet | G4: captured | H4: 22
A5: TXN100003 | B5: 92 | C5: 22 | D5: 46051.542 | E5: 49 | F5: Netbanking | G5: captured | H5: 100
A6: TXN100004 | B6: 343 | C6: 16 | D6: 46052.577 | E6: 99 | F6: UPI | G6: captured | H6: 34
A7: TXN100005 | B7: 196 | C7: 3 | D7: 46028.921 | E7: 99 | F7: UPI | G7: captured | H7: 60
A8: TXN100006 | B8: 236 | C8: 23 | D8: 46030.286 | E8: 99 | F8: Wallet | G8: captured | H8: 39
A9: TXN100007 | B9: 13 | C9: 13 | D9: 46049.301 | E9: 99 | F9: UPI | G9: captured | H9: 51
A10: TXN100008 | B10: 36 | C10: 18 | D10: 46033.372 | E10: 799 | F10: UPI | G10: captured | H10: 44
A11: TXN100009 | B11: 348 | C11: 35 | D11: 46043.684 | E11: 299 | F11: UPI | G11: captured | H11: 42
A12: TXN100010 | B12: 134 | C12: 12 | D12: 46023.164 | E12: 49 | F12: UPI | G12: captured | H12: 74
A13: TXN100011 | B13: 306 | C13: 28 | D13: 46031.046 | E13: 2999 | F13: Card | G13: failed | H13: 44
... A548: TXN300031 | B548: 345 | C548: 12 | D548: 46045.377 | E548: 399 | F548: Card | G548: captured | H548: 69

Sheet Merchants
A1: merchant_id | B1: merchant_name | C1: category | D1: region
A2: 1 | B2: Merchant_001 | C2: ecommerce | D2: South
A3: 2 | B3: Merchant_002 | C3: grocery | D3: West
A4: 3 | B4: Merchant_003 | C4: grocery | D4: East
A5: 4 | B5: Merchant_004 | C5: ecommerce | D5: East
A6: 5 | B6: Merchant_005 | C6: recharge | D6: South
A7: 6 | B7: Merchant_006 | C7: food_delivery | D7: South
A8: 7 | B8: Merchant_007 | C8: food_delivery | D8: East
A9: 8 | B9: Merchant_008 | C9: food_delivery | D9: North
A10: 9 | B10: Merchant_009 | C10: ecommerce | D10: North
A11: 10 | B11: Merchant_010 | C11: grocery | D11: West
A12: 11 | B12: Merchant_011 | C12: ecommerce | D12: North
A13: 12 | B13: Merchant_012 | C13: ecommerce | D13: East
... A41: 40 | B41: Merchant_040 | C41: entertainment | D41: South

Sheet MDR Rates
B1: Payment Method | C1: UPI | D1: Wallet | E1: Card | F1: Netbanking
B2: MDR Fee % | C2: 0 | D2: 0.01 | E2: 0.02 | F2: 0.015

Sheet Transactions-view sheet
A1: transaction_id | B1: user_id | C1: merchant_id | D1: transaction_time | E1: amount_inr | F1: payment_method | G1: status | H1: risk_score | I1: merchant_name | J1: category | K1: region | L1: MDR Fee % | M1: Date | N1: Daily Total (Using Sum IFs) | O1: Daily Total (Using Pivot Table) | P1: High Value Flag
A2: TXN100000 | B2: 350 | C2: 16 | D2: 46051.467 | E2: 2999 | F2: Wallet | G2: captured | H2: 85 | I2: =IFERROR(VLOOKUP(C2,Merchants!$A$2:$D$41,2,FALSE),"Merchant not found") -> Merchant_016 | J2: =IFERROR(VLOOKUP(C2,Merchants!$A$2:$D$41,3,FALSE),"Merchant not found") -> bill_payment | K2: =IFERROR(VLOOKUP(C2,Merchants!$A$2:$D$41,4,FALSE),"Merchant not found") -> West | L2: =_xlfn.IFNA(HLOOKUP(F2,'MDR Rates'!$C$1:$F$2,2,FALSE),"N/A") -> 0.01 | M2: =INT(D2) -> 46051 | N2: =SUMIFS($E$2:$E$548,$C$2:$C$548,C2,$M$2:$M$548,M2) -> 2999 | O2: =GETPIVOTDATA("amount_inr",'Pivot Table'!$A$3,"merchant_name",I2,"Date",M2) -> 2999 | P2: =IF(AND(O2>5000,K2<>"East"),"High-Value Merchant Day","Standard") -> Standard
A3: TXN100001 | B3: 287 | C3: 27 | D3: 46026.492 | E3: 49 | F3: UPI | G3: captured | H3: 79 | I3: =IFERROR(VLOOKUP(C3,Merchants!$A$2:$D$41,2,FALSE),"Merchant not found") -> Merchant_027 | J3: =IFERROR(VLOOKUP(C3,Merchants!$A$2:$D$41,3,FALSE),"Merchant not found") -> ecommerce | K3: =IFERROR(VLOOKUP(C3,Merchants!$A$2:$D$41,4,FALSE),"Merchant not found") -> North | L3: =_xlfn.IFNA(HLOOKUP(F3,'MDR Rates'!$C$1:$F$2,2,FALSE),"N/A") -> 0 | M3: =INT(D3) -> 46026 | N3: =SUMIFS($E$2:$E$548,$C$2:$C$548,C3,$M$2:$M$548,M3) -> 49 | O3: =GETPIVOTDATA("amount_inr",'Pivot Table'!$A$3,"merchant_name",I3,"Date",M3) -> 49 | P3: =IF(AND(O3>5000,K3<>"East"),"High-Value Merchant Day","Standard") -> Standard
A4: TXN100002 | B4: 122 | C4: 11 | D4: 46046.208 | E4: 1499 | F4: Wallet | G4: captured | H4: 22 | I4: =IFERROR(VLOOKUP(C4,Merchants!$A$2:$D$41,2,FALSE),"Merchant not found") -> Merchant_011 | J4: =IFERROR(VLOOKUP(C4,Merchants!$A$2:$D$41,3,FALSE),"Merchant not found") -> ecommerce | K4: =IFERROR(VLOOKUP(C4,Merchants!$A$2:$D$41,4,FALSE),"Merchant not found") -> North | L4: =_xlfn.IFNA(HLOOKUP(F4,'MDR Rates'!$C$1:$F$2,2,FALSE),"N/A") -> 0.01 | M4: =INT(D4) -> 46046 | N4: =SUMIFS($E$2:$E$548,$C$2:$C$548,C4,$M$2:$M$548,M4) -> 1798 | O4: =GETPIVOTDATA("amount_inr",'Pivot Table'!$A$3,"merchant_name",I4,"Date",M4) -> 1798 | P4: =IF(AND(O4>5000,K4<>"East"),"High-Value Merchant Day","Standard") -> Standard
A5: TXN100003 | B5: 92 | C5: 22 | D5: 46051.542 | E5: 49 | F5: Netbanking | G5: captured | H5: 100 | I5: =IFERROR(VLOOKUP(C5,Merchants!$A$2:$D$41,2,FALSE),"Merchant not found") -> Merchant_022 | J5: =IFERROR(VLOOKUP(C5,Merchants!$A$2:$D$41,3,FALSE),"Merchant not found") -> travel | K5: =IFERROR(VLOOKUP(C5,Merchants!$A$2:$D$41,4,FALSE),"Merchant not found") -> South | L5: =_xlfn.IFNA(HLOOKUP(F5,'MDR Rates'!$C$1:$F$2,2,FALSE),"N/A") -> 0.015 | M5: =INT(D5) -> 46051 | N5: =SUMIFS($E$2:$E$548,$C$2:$C$548,C5,$M$2:$M$548,M5) -> 49 | O5: =GETPIVOTDATA("amount_inr",'Pivot Table'!$A$3,"merchant_name",I5,"Date",M5) -> 49 | P5: =IF(AND(O5>5000,K5<>"East"),"High-Value Merchant Day","Standard") -> Standard
A6: TXN100004 | B6: 343 | C6: 16 | D6: 46052.577 | E6: 99 | F6: UPI | G6: captured | H6: 34 | I6: =IFERROR(VLOOKUP(C6,Merchants!$A$2:$D$41,2,FALSE),"Merchant not found") -> Merchant_016 | J6: =IFERROR(VLOOKUP(C6,Merchants!$A$2:$D$41,3,FALSE),"Merchant not found") -> bill_payment | K6: =IFERROR(VLOOKUP(C6,Merchants!$A$2:$D$41,4,FALSE),"Merchant not found") -> West | L6: =_xlfn.IFNA(HLOOKUP(F6,'MDR Rates'!$C$1:$F$2,2,FALSE),"N/A") -> 0 | M6: =INT(D6) -> 46052 | N6: =SUMIFS($E$2:$E$548,$C$2:$C$548,C6,$M$2:$M$548,M6) -> 898 | O6: =GETPIVOTDATA("amount_inr",'Pivot Table'!$A$3,"merchant_name",I6,"Date",M6) -> 898 | P6: =IF(AND(O6>5000,K6<>"East"),"High-Value Merchant Day","Standard") -> Standard
A7: TXN100005 | B7: 196 | C7: 3 | D7: 46028.921 | E7: 99 | F7: UPI | G7: captured | H7: 60 | I7: =IFERROR(VLOOKUP(C7,Merchants!$A$2:$D$41,2,FALSE),"Merchant not found") -> Merchant_003 | J7: =IFERROR(VLOOKUP(C7,Merchants!$A$2:$D$41,3,FALSE),"Merchant not found") -> grocery | K7: =IFERROR(VLOOKUP(C7,Merchants!$A$2:$D$41,4,FALSE),"Merchant not found") -> East | L7: =_xlfn.IFNA(HLOOKUP(F7,'MDR Rates'!$C$1:$F$2,2,FALSE),"N/A") -> 0 | M7: =INT(D7) -> 46028 | N7: =SUMIFS($E$2:$E$548,$C$2:$C$548,C7,$M$2:$M$548,M7) -> 898 | O7: =GETPIVOTDATA("amount_inr",'Pivot Table'!$A$3,"merchant_name",I7,"Date",M7) -> 898 | P7: =IF(AND(O7>5000,K7<>"East"),"High-Value Merchant Day","Standard") -> Standard
A8: TXN100006 | B8: 236 | C8: 23 | D8: 46030.286 | E8: 99 | F8: Wallet | G8: captured | H8: 39 | I8: =IFERROR(VLOOKUP(C8,Merchants!$A$2:$D$41,2,FALSE),"Merchant not found") -> Merchant_023 | J8: =IFERROR(VLOOKUP(C8,Merchants!$A$2:$D$41,3,FALSE),"Merchant not found") -> travel | K8: =IFERROR(VLOOKUP(C8,Merchants!$A$2:$D$41,4,FALSE),"Merchant not found") -> North | L8: =_xlfn.IFNA(HLOOKUP(F8,'MDR Rates'!$C$1:$F$2,2,FALSE),"N/A") -> 0.01 | M8: =INT(D8) -> 46030 | N8: =SUMIFS($E$2:$E$548,$C$2:$C$548,C8,$M$2:$M$548,M8) -> 99 | O8: =GETPIVOTDATA("amount_inr",'Pivot Table'!$A$3,"merchant_name",I8,"Date",M8) -> 99 | P8: =IF(AND(O8>5000,K8<>"East"),"High-Value Merchant Day","Standard") -> Standard
A9: TXN100007 | B9: 13 | C9: 13 | D9: 46049.301 | E9: 99 | F9: UPI | G9: captured | H9: 51 | I9: =IFERROR(VLOOKUP(C9,Merchants!$A$2:$D$41,2,FALSE),"Merchant not found") -> Merchant_013 | J9: =IFERROR(VLOOKUP(C9,Merchants!$A$2:$D$41,3,FALSE),"Merchant not found") -> travel | K9: =IFERROR(VLOOKUP(C9,Merchants!$A$2:$D$41,4,FALSE),"Merchant not found") -> East | L9: =_xlfn.IFNA(HLOOKUP(F9,'MDR Rates'!$C$1:$F$2,2,FALSE),"N/A") -> 0 | M9: =INT(D9) -> 46049 | N9: =SUMIFS($E$2:$E$548,$C$2:$C$548,C9,$M$2:$M$548,M9) -> 99 | O9: =GETPIVOTDATA("amount_inr",'Pivot Table'!$A$3,"merchant_name",I9,"Date",M9) -> 99 | P9: =IF(AND(O9>5000,K9<>"East"),"High-Value Merchant Day","Standard") -> Standard
A10: TXN100008 | B10: 36 | C10: 18 | D10: 46033.372 | E10: 799 | F10: UPI | G10: captured | H10: 44 | I10: =IFERROR(VLOOKUP(C10,Merchants!$A$2:$D$41,2,FALSE),"Merchant not found") -> Merchant_018 | J10: =IFERROR(VLOOKUP(C10,Merchants!$A$2:$D$41,3,FALSE),"Merchant not found") -> grocery | K10: =IFERROR(VLOOKUP(C10,Merchants!$A$2:$D$41,4,FALSE),"Merchant not found") -> West | L10: =_xlfn.IFNA(HLOOKUP(F10,'MDR Rates'!$C$1:$F$2,2,FALSE),"N/A") -> 0 | M10: =INT(D10) -> 46033 | N10: =SUMIFS($E$2:$E$548,$C$2:$C$548,C10,$M$2:$M$548,M10) -> 799 | O10: =GETPIVOTDATA("amount_inr",'Pivot Table'!$A$3,"merchant_name",I10,"Date",M10) -> 799 | P10: =IF(AND(O10>5000,K10<>"East"),"High-Value Merchant Day","Standard") -> Standard
A11: TXN100009 | B11: 348 | C11: 35 | D11: 46043.684 | E11: 299 | F11: UPI | G11: captured | H11: 42 | I11: =IFERROR(VLOOKUP(C11,Merchants!$A$2:$D$41,2,FALSE),"Merchant not found") -> Merchant_035 | J11: =IFERROR(VLOOKUP(C11,Merchants!$A$2:$D$41,3,FALSE),"Merchant not found") -> recharge | K11: =IFERROR(VLOOKUP(C11,Merchants!$A$2:$D$41,4,FALSE),"Merchant not found") -> East | L11: =_xlfn.IFNA(HLOOKUP(F11,'MDR Rates'!$C$1:$F$2,2,FALSE),"N/A") -> 0 | M11: =INT(D11) -> 46043 | N11: =SUMIFS($E$2:$E$548,$C$2:$C$548,C11,$M$2:$M$548,M11) -> 299 | O11: =GETPIVOTDATA("amount_inr",'Pivot Table'!$A$3,"merchant_name",I11,"Date",M11) -> 299 | P11: =IF(AND(O11>5000,K11<>"East"),"High-Value Merchant Day","Standard") -> Standard
A12: TXN100010 | B12: 134 | C12: 12 | D12: 46023.164 | E12: 49 | F12: UPI | G12: captured | H12: 74 | I12: =IFERROR(VLOOKUP(C12,Merchants!$A$2:$D$41,2,FALSE),"Merchant not found") -> Merchant_012 | J12: =IFERROR(VLOOKUP(C12,Merchants!$A$2:$D$41,3,FALSE),"Merchant not found") -> ecommerce | K12: =IFERROR(VLOOKUP(C12,Merchants!$A$2:$D$41,4,FALSE),"Merchant not found") -> East | L12: =_xlfn.IFNA(HLOOKUP(F12,'MDR Rates'!$C$1:$F$2,2,FALSE),"N/A") -> 0 | M12: =INT(D12) -> 46023 | N12: =SUMIFS($E$2:$E$548,$C$2:$C$548,C12,$M$2:$M$548,M12) -> 548 | O12: =GETPIVOTDATA("amount_inr",'Pivot Table'!$A$3,"merchant_name",I12,"Date",M12) -> 548 | P12: =IF(AND(O12>5000,K12<>"East"),"High-Value Merchant Day","Standard") -> Standard
A13: TXN100011 | B13: 306 | C13: 28 | D13: 46031.046 | E13: 2999 | F13: Card | G13: failed | H13: 44 | I13: =IFERROR(VLOOKUP(C13,Merchants!$A$2:$D$41,2,FALSE),"Merchant not found") -> Merchant_028 | J13: =IFERROR(VLOOKUP(C13,Merchants!$A$2:$D$41,3,FALSE),"Merchant not found") -> ecommerce | K13: =IFERROR(VLOOKUP(C13,Merchants!$A$2:$D$41,4,FALSE),"Merchant not found") -> South | L13: =_xlfn.IFNA(HLOOKUP(F13,'MDR Rates'!$C$1:$F$2,2,FALSE),"N/A") -> 0.02 | M13: =INT(D13) -> 46031 | N13: =SUMIFS($E$2:$E$548,$C$2:$C$548,C13,$M$2:$M$548,M13) -> 2999 | O13: =GETPIVOTDATA("amount_inr",'Pivot Table'!$A$3,"merchant_name",I13,"Date",M13) -> 2999 | P13: =IF(AND(O13>5000,K13<>"East"),"High-Value Merchant Day","Standard") -> Standard
... A548: TXN300031 | B548: 345 | C548: 12 | D548: 46045.377 | E548: 399 | F548: Card | G548: captured | H548: 69 | I548: =IFERROR(VLOOKUP(C548,Merchants!$A$2:$D$41,2,FALSE),"Merchant not found") -> Merchant_012 | J548: =IFERROR(VLOOKUP(C548,Merchants!$A$2:$D$41,3,FALSE),"Merchant not found") -> ecommerce | K548: =IFERROR(VLOOKUP(C548,Merchants!$A$2:$D$41,4,FALSE),"Merchant not found") -> East | L548: =_xlfn.IFNA(HLOOKUP(F548,'MDR Rates'!$C$1:$F$2,2,FALSE),"N/A") -> 0.02 | M548: =INT(D548) -> 46045 | N548: =SUMIFS($E$2:$E$548,$C$2:$C$548,C548,$M$2:$M$548,M548) -> 448 | O548: =GETPIVOTDATA("amount_inr",'Pivot Table'!$A$3,"merchant_name",I548,"Date",M548) -> 448 | P548: =IF(AND(O548>5000,K548<>"East"),"High-Value Merchant Day","Standard") -> Standard

Sheet Pivot Table
A2: Flagging - High Merchant Value | F2: Pivot Table - Summary
A3: Date | B3: merchant_name | C3: Sum of amount_inr | G3: status | H3: Values
A4: 46023 | B4: Merchant_005 | C4: 499 | G4: captured | J4: chargeback | M4: failed | P4: Total Distinct Count of Date | Q4: Total Count of transaction_id | R4: Total Sum of amount_inr
A5: 46023 | B5: Merchant_006 | C5: 49 | F5: merchant_id | G5: Distinct Count of Date | H5: Count of transaction_id | I5: Sum of amount_inr | J5: Distinct Count of Date | K5: Count of transaction_id | L5: Sum of amount_inr | M5: Distinct Count of Date | N5: Count of transaction_id | O5: Sum of amount_inr
A6: 46023 | B6: Merchant_009 | C6: 499 | F6: 39 | G6: 8 | H6: 9 | I6: 11291 | J6: 2 | K6: 3 | L6: 10997 | M6: 1 | N6: 1 | O6: 399 | P6: 10 | Q6: 13 | R6: 22687
A7: 46023 | B7: Merchant_012 | C7: 548 | F7: 13 | G7: 9 | H7: 10 | I7: 10390 | J7: 1 | K7: 1 | L7: 4999 | M7: 1 | N7: 1 | O7: 2999 | P7: 11 | Q7: 12 | R7: 18388
A8: 46023 | B8: Merchant_014 | C8: 299 | F8: 7 | G8: 10 | H8: 12 | I8: 11638 | J8: 1 | K8: 1 | L8: 1999 | M8: 2 | N8: 3 | O8: 2297 | P8: 11 | Q8: 16 | R8: 15934
A9: 46023 | B9: Merchant_015 | C9: 499 | F9: 25 | G9: 11 | H9: 16 | I9: 12534 | J9: 1 | K9: 1 | L9: 2999 | P9: 11 | Q9: 17 | R9: 15533
A10: 46023 | B10: Merchant_017 | C10: 1499 | F10: 27 | G10: 10 | H10: 12 | I10: 8038 | J10: 2 | K10: 3 | L10: 4047 | M10: 1 | N10: 1 | O10: 1499 | P10: 13 | Q10: 16 | R10: 13584
A11: 46023 | B11: Merchant_021 | C11: 5298 | F11: 10 | G11: 9 | H11: 11 | I11: 7639 | J11: 2 | K11: 2 | L11: 5048 | M11: 1 | N11: 1 | O11: 399 | P11: 12 | Q11: 14 | R11: 13086
A12: 46023 | B12: Merchant_022 | C12: 799 | F12: 29 | G12: 12 | H12: 14 | I12: 5686 | J12: 2 | K12: 3 | L12: 3897 | M12: 2 | N12: 2 | O12: 3498 | P12: 13 | Q12: 19 | R12: 13081
A13: 46023 | B13: Merchant_027 | C13: 149 | F13: 17 | G13: 9 | H13: 12 | I13: 12738 | M13: 1 | N13: 1 | O13: 299 | P13: 10 | Q13: 13 | R13: 13037
A14: 46023 | B14: Merchant_035 | C14: 798 | F14: 37 | G14: 15 | H14: 17 | I14: 10833 | J14: 1 | K14: 1 | L14: 1999 | M14: 1 | N14: 1 | O14: 99 | P14: 16 | Q14: 19 | R14: 12931
A15: 46023 | B15: Merchant_036 | C15: 149 | F15: 19 | G15: 10 | H15: 11 | I15: 7239 | J15: 1 | K15: 1 | L15: 4999 | M15: 2 | N15: 2 | O15: 598 | P15: 12 | Q15: 14 | R15: 12836
A16: 46023 | B16: Merchant_037 | C16: 598 | F16: 36 | G16: 11 | H16: 15 | I16: 11535 | J16: 1 | K16: 1 | L16: 999 | P16: 12 | Q16: 16 | R16: 12534
A17: 46023 | B17: Merchant_040 | C17: 299 | F17: 22 | G17: 11 | H17: 14 | I17: 11336 | M17: 2 | N17: 2 | O17: 1198 | P17: 11 | Q17: 16 | R17: 12534
A18: 01/01/2026 Total | C18: 11982 | F18: 16 | G18: 13 | H18: 17 | I18: 10183 | M18: 3 | N18: 3 | O18: 947 | P18: 15 | Q18: 20 | R18: 11130
A19: 46024 | B19: Merchant_004 | C19: 149 | F19: 11 | G19: 7 | H19: 8 | I19: 9292 | J19: 1 | K19: 1 | L19: 149 | M19: 1 | N19: 1 | O19: 1499 | P19: 9 | Q19: 10 | R19: 10940
A20: 46024 | B20: Merchant_007 | C20: 3797 | F20: 1 | G20: 6 | H20: 8 | I20: 10142 | M20: 1 | N20: 1 | O20: 299 | P20: 7 | Q20: 9 | R20: 10441
A21: 46024 | B21: Merchant_008 | C21: 299 | F21: 12 | G21: 9 | H21: 11 | I21: 9389 | M21: 2 | N21: 2 | O21: 998 | P21: 9 | Q21: 13 | R21: 10387
A22: 46024 | B22: Merchant_014 | C22: 1499 | F22: 33 | G22: 9 | H22: 10 | I22: 10190 | M22: 1 | N22: 1 | O22: 149 | P22: 10 | Q22: 11 | R22: 10339
A23: 46024 | B23: Merchant_016 | C23: 499 | F23: 34 | G23: 11 | H23: 15 | I23: 9635 | M23: 1 | N23: 1 | O23: 399 | P23: 12 | Q23: 16 | R23: 10034
A24: 46024 | B24: Merchant_017 | C24: 299 | F24: 28 | G24: 7 | H24: 7 | I24: 4493 | J24: 1 | K24: 1 | L24: 1999 | M24: 2 | N24: 2 | O24: 3048 | P24: 10 | Q24: 10 | R24: 9540
A25: 46024 | B25: Merchant_019 | C25: 149 | F25: 35 | G25: 11 | H25: 12 | I25: 8688 | M25: 2 | N25: 2 | O25: 598 | P25: 11 | Q25: 14 | R25: 9286
A26: 46024 | B26: Merchant_020 | C26: 49 | F26: 21 | G26: 13 | H26: 13 | I26: 3887 | M26: 1 | N26: 1 | O26: 4999 | P26: 13 | Q26: 14 | R26: 8886
A27: 46024 | B27: Merchant_025 | C27: 99 | F27: 40 | G27: 10 | H27: 11 | I27: 3039 | J27: 2 | K27: 2 | L27: 5148 | M27: 2 | N27: 2 | O27: 548 | P27: 13 | Q27: 15 | R27: 8735
A28: 46024 | B28: Merchant_026 | C28: 399 | F28: 3 | G28: 13 | H28: 16 | I28: 8084 | J28: 1 | K28: 1 | L28: 149 | P28: 13 | Q28: 17 | R28: 8233
A29: 46024 | B29: Merchant_034 | C29: 548 | F29: 32 | G29: 9 | H29: 11 | I29: 2589 | J29: 1 | K29: 1 | L29: 1999 | M29: 2 | N29: 2 | O29: 3498 | P29: 12 | Q29: 14 | R29: 8086
A30: 46024 | B30: Merchant_035 | C30: 1847 | F30: 30 | G30: 12 | H30: 16 | I30: 7384 | M30: 1 | N30: 1 | O30: 499 | P30: 13 | Q30: 17 | R30: 7883
A31: 46024 | B31: Merchant_036 | C31: 299 | F31: 15 | G31: 9 | H31: 11 | I31: 7439 | M31: 1 | N31: 1 | O31: 399 | P31: 10 | Q31: 12 | R31: 7838
A32: 46024 | B32: Merchant_037 | C32: 2999 | F32: 6 | G32: 12 | H32: 13 | I32: 6637 | J32: 1 | K32: 1 | L32: 799 | P32: 12 | Q32: 14 | R32: 7436
A33: 46024 | B33: Merchant_039 | C33: 499 | F33: 8 | G33: 11 | H33: 14 | I33: 7086 | J33: 1 | K33: 1 | L33: 49 | M33: 1 | N33: 1 | O33: 299 | P33: 13 | Q33: 16 | R33: 7434
A34: 02/01/2026 Total | C34: 13430 | F34: 18 | G34: 9 | H34: 11 | I34: 7089 | P34: 9 | Q34: 11 | R34: 7089
A35: 46025 | B35: Merchant_003 | C35: 198 | F35: 4 | G35: 7 | H35: 9 | I35: 6941 | P35: 7 | Q35: 9 | R35: 6941
A36: 46025 | B36: Merchant_005 | C36: 499 | F36: 14 | G36: 10 | H36: 11 | I36: 6189 | M36: 1 | N36: 1 | O36: 299 | P36: 11 | Q36: 12 | R36: 6488
A37: 46025 | B37: Merchant_006 | C37: 799 | F37: 5 | G37: 8 | H37: 10 | I37: 5340 | M37: 1 | N37: 1 | O37: 499 | P37: 9 | Q37: 11 | R37: 5839
A38: 46025 | B38: Merchant_007 | C38: 149 | F38: 26 | G38: 8 | H38: 9 | I38: 2991 | M38: 3 | N38: 3 | O38: 2197 | P38: 11 | Q38: 12 | R38: 5188
A39: 46025 | B39: Merchant_008 | C39: 299 | F39: 9 | G39: 13 | H39: 15 | I39: 4485 | M39: 3 | N39: 3 | O39: 497 | P39: 14 | Q39: 18 | R39: 4982
A40: 46025 | B40: Merchant_014 | C40: 149 | F40: 31 | G40: 10 | H40: 10 | I40: 2640 | J40: 1 | K40: 1 | L40: 49 | M40: 3 | N40: 4 | O40: 2146 | P40: 14 | Q40: 15 | R40: 4835
A41: 46025 | B41: Merchant_016 | C41: 99 | F41: 20 | G41: 7 | H41: 8 | I41: 4192 | M41: 1 | N41: 1 | O41: 49 | P41: 8 | Q41: 9 | R41: 4241
...
